
<!DOCTYPE HTML>

<html lang="en" class="_theme-default">

<head>
  <meta charset="utf-8">
  <title>Exception Handling - Kotlin - W3cubDocs</title>
  
  <meta name="description" content=" Table of contents ">
  <meta name="keywords" content="exception, handling, kotlin">
  <meta name="HandheldFriendly" content="True">
  <meta name="MobileOptimized" content="320">
  <meta name="viewport" content="width=device-width, initial-scale=1">
  <meta name="mobile-web-app-capable" content="yes">
  
  <link rel="canonical" href="https://docs.w3cub.com/kotlin/docs/reference/coroutines/exception-handling.html">
  <link href="/favicon.png" rel="icon">
  <link rel="stylesheet" type="text/css" href="/assets/application-e4ebd3a2a5652ff55173659804c4390a004917f3bdd17b5bb3ba78ea5c9c46fe181cadaac34517ccd815f5bdc982bbfe67179d6f4ac2f084ef2265e2a3dc8dc5.css" integrity="sha512-5OvToqVlL/VRc2WYBMQ5CgBJF/O90Xtbs7p46lycRv4YHK2qw0UXzNgV9b3Jgrv+Zxedb0rC8ITvImXio9yNxQ==" crossorigin="anonymous">
  <script type="text/javascript" integrity="sha512-EpkDeu98lN/jPKijllzVWdRg/dUSSMCaldYZNFz6bcNoBvpWRNz0HSTRQJ3ENmQc5Cuj1zDW1vHd7b0DzpOgyA==" crossorigin="anonymous" src="/assets/application-1299037aef7c94dfe33ca8a3965cd559d460fdd51248c09a95d619345cfa6dc36806fa5644dcf41d24d1409dc436641ce42ba3d730d6d6f1ddedbd03ce93a0c8.js"></script>
  <script src="/json/kotlin.js"></script>
  
  <script type="text/javascript">
    var _gaq = _gaq || [];
    _gaq.push(['_setAccount', 'UA-71174418-1']);
    _gaq.push(['_trackPageview']);

    (function() {
      var ga = document.createElement('script'); ga.type = 'text/javascript'; ga.async = true;
      ga.src = ('https:' == document.location.protocol ? 'https://ssl' : 'http://www') + '.google-analytics.com/ga.js';
      var s = document.getElementsByTagName('script')[0]; s.parentNode.insertBefore(ga, s);
    })();
  </script>
  <script data-ad-client="ca-pub-2572770204602497" async src="https://pagead2.googlesyndication.com/pagead/js/adsbygoogle.js"></script>
  <script async custom-element="amp-auto-ads"
  src="https://cdn.ampproject.org/v0/amp-auto-ads-0.1.js">
</script>


</head>

<body>
	<amp-auto-ads type="adsense"
              data-ad-client="ca-pub-2572770204602497">
	</amp-auto-ads>
	<div class="_app">
	<header class="_header">
  
  <form class="_search">
    <input type="search" class="_search-input" placeholder="Search&hellip;" autocomplete="off" autocapitalize="off" autocorrect="off" spellcheck="false" maxlength="20">
    <a class="_search-clear"></a>
    <div class="_search-tag"></div>
  </form>
  
  <a class="_home-link" href="/" ></a>
  <a class="_menu-link"></a>
  <h1 class="_logo">
    <a href="/" class="_nav-link" title="API Documentation Browser">W3cubDocs</a>
  </h1>
  
  <span class="_logo-sub-nav">/</span><span class="_logo-sub-nav"><a href="/kotlin/" class="_nav-link" title="" style="margin-left:0;">Kotlin</a></span>
  
  <nav class="_nav">
    <a href="https://tools.w3cub.com/?_sp=docs" target="_blank" class="_nav-link ">W3cubTools</a>
    <a href="/cheatsheets/" class="_nav-link ">Cheatsheets</a>
    <a href="/about/" class="_nav-link ">About</a>
  </nav>
</header>
	<section class="_sidebar">
		<div class="_list-wrap">
			<div class="_list">
			
			</div>
		</div>
	</section>
	<section class="_container ">
		<div class="_content">
			<ins class="adsbygoogle"
     style="display:block"
     data-ad-client="ca-pub-2572770204602497"
     data-ad-slot="6861657091"
     data-ad-format="link"
     data-full-width-responsive="true"></ins>
<script>
     (adsbygoogle = window.adsbygoogle || []).push({});
</script>
			<div class="_page _kotlin">
				
				
<p class="typo-para"><strong class="typo-strong">Table of contents</strong></p>  <ul class="typo-list typo-list_type_simple"> <li class="typo-list__item">
<a class="typo-link" href="#exception-handling">Exception Handling</a> <ul class="typo-list typo-list_type_simple"> <li class="typo-list__item"><a class="typo-link" href="#exception-propagation">Exception propagation</a></li> <li class="typo-list__item"><a class="typo-link" href="#coroutineexceptionhandler">CoroutineExceptionHandler</a></li> <li class="typo-list__item"><a class="typo-link" href="#cancellation-and-exceptions">Cancellation and exceptions</a></li> <li class="typo-list__item"><a class="typo-link" href="#exceptions-aggregation">Exceptions aggregation</a></li> <li class="typo-list__item">
<a class="typo-link" href="#supervision">Supervision</a> <ul class="typo-list typo-list_type_simple"> <li class="typo-list__item"><a class="typo-link" href="#supervision-job">Supervision job</a></li> <li class="typo-list__item"><a class="typo-link" href="#supervision-scope">Supervision scope</a></li> <li class="typo-list__item"><a class="typo-link" href="#exceptions-in-supervised-coroutines">Exceptions in supervised coroutines</a></li> </ul> </li> </ul> </li> </ul>  <h2 class="typo-header typo-h2" id="exception-handling">Exception Handling</h2> <p class="typo-para">This section covers exception handling and cancellation on exceptions. We already know that a cancelled coroutine throws <a class="typo-link" href="https://kotlin.github.io/kotlinx.coroutines/kotlinx-coroutines-core/kotlinx.coroutines/-cancellation-exception/index.html">CancellationException</a> in suspension points and that it is ignored by the coroutines' machinery. Here we look at what happens if an exception is thrown during cancellation or multiple children of the same coroutine throw an exception.</p> <h3 class="typo-header typo-h3" id="exception-propagation">Exception propagation</h3> <p class="typo-para">Coroutine builders come in two flavors: propagating exceptions automatically (<a class="typo-link" href="https://kotlin.github.io/kotlinx.coroutines/kotlinx-coroutines-core/kotlinx.coroutines/launch.html">launch</a> and <a class="typo-link" href="https://kotlin.github.io/kotlinx.coroutines/kotlinx-coroutines-core/kotlinx.coroutines.channels/actor.html">actor</a>) or exposing them to users (<a class="typo-link" href="https://kotlin.github.io/kotlinx.coroutines/kotlinx-coroutines-core/kotlinx.coroutines/async.html">async</a> and <a class="typo-link" href="https://kotlin.github.io/kotlinx.coroutines/kotlinx-coroutines-core/kotlinx.coroutines.channels/produce.html">produce</a>). When these builders are used to create a <em>root</em> coroutine, that is not a <em>child</em> of another coroutine, the former builders treat exceptions as <strong class="typo-strong">uncaught</strong> exceptions, similar to Java's <code>Thread.uncaughtExceptionHandler</code>, while the latter are relying on the user to consume the final exception, for example via <a class="typo-link" href="https://kotlin.github.io/kotlinx.coroutines/kotlinx-coroutines-core/kotlinx.coroutines/-deferred/await.html">await</a> or <a class="typo-link" href="https://kotlin.github.io/kotlinx.coroutines/kotlinx-coroutines-core/kotlinx.coroutines.channels/-receive-channel/receive.html">receive</a> (<a class="typo-link" href="https://kotlin.github.io/kotlinx.coroutines/kotlinx-coroutines-core/kotlinx.coroutines.channels/produce.html">produce</a> and <a class="typo-link" href="https://kotlin.github.io/kotlinx.coroutines/kotlinx-coroutines-core/kotlinx.coroutines.channels/-receive-channel/receive.html">receive</a> are covered later in <a class="typo-link" href="https://github.com/Kotlin/kotlinx.coroutines/blob/master/docs/channels.md">Channels</a> section).</p> <p class="typo-para">It can be demonstrated by a simple example that creates root coroutines using the <a class="typo-link" href="https://kotlin.github.io/kotlinx.coroutines/kotlinx-coroutines-core/kotlinx.coroutines/-global-scope/index.html">GlobalScope</a>:</p> <div class="sample"> <pre data-language="kotlin">import kotlinx.coroutines.*

fun main() = runBlocking {
    val job = GlobalScope.launch { // root coroutine with launch
        println("Throwing exception from launch")
        throw IndexOutOfBoundsException() // Will be printed to the console by Thread.defaultUncaughtExceptionHandler
    }
    job.join()
    println("Joined failed job")
    val deferred = GlobalScope.async { // root coroutine with async
        println("Throwing exception from async")
        throw ArithmeticException() // Nothing is printed, relying on user to call await
    }
    try {
        deferred.await()
        println("Unreached")
    } catch (e: ArithmeticException) {
        println("Caught ArithmeticException")
    }
}
</pre> </div> <blockquote class="typo-quote"> <p class="typo-para">You can get the full code <a class="typo-link" href="https://github.com/kotlin/kotlinx.coroutines/blob/master/kotlinx-coroutines-core/jvm/test/guide/example-exceptions-01.kt">here</a>.</p> </blockquote> <p class="typo-para">The output of this code is (with <a class="typo-link" href="https://github.com/Kotlin/kotlinx.coroutines/blob/master/docs/coroutine-context-and-dispatchers.md#debugging-coroutines-and-threads">debug</a>):</p> <pre>Throwing exception from launch
Exception in thread "DefaultDispatcher-worker-2 @coroutine#2" java.lang.IndexOutOfBoundsException
Joined failed job
Throwing exception from async
Caught ArithmeticException
</pre>  <h3 class="typo-header typo-h3" id="coroutineexceptionhandler">CoroutineExceptionHandler</h3> <p class="typo-para">It is possible to customize the default behavior of printing <strong class="typo-strong">uncaught</strong> exceptions to the console. <a class="typo-link" href="https://kotlin.github.io/kotlinx.coroutines/kotlinx-coroutines-core/kotlinx.coroutines/-coroutine-exception-handler/index.html">CoroutineExceptionHandler</a> context element on a <em>root</em> coroutine can be used as generic <code>catch</code> block for this root coroutine and all its children where custom exception handling may take place. It is similar to <a class="typo-link" href="https://docs.oracle.com/javase/8/docs/api/java/lang/Thread.html#setUncaughtExceptionHandler(java.lang.Thread.UncaughtExceptionHandler)"><code>Thread.uncaughtExceptionHandler</code></a>. You cannot recover from the exception in the <code>CoroutineExceptionHandler</code>. The coroutine had already completed with the corresponding exception when the handler is called. Normally, the handler is used to log the exception, show some kind of error message, terminate, and/or restart the application.</p> <p class="typo-para">On JVM it is possible to redefine global exception handler for all coroutines by registering <a class="typo-link" href="https://kotlin.github.io/kotlinx.coroutines/kotlinx-coroutines-core/kotlinx.coroutines/-coroutine-exception-handler/index.html">CoroutineExceptionHandler</a> via <a class="typo-link" href="https://docs.oracle.com/javase/8/docs/api/java/util/ServiceLoader.html"><code>ServiceLoader</code></a>. Global exception handler is similar to <a class="typo-link" href="https://docs.oracle.com/javase/8/docs/api/java/lang/Thread.html#setDefaultUncaughtExceptionHandler(java.lang.Thread.UncaughtExceptionHandler)"><code>Thread.defaultUncaughtExceptionHandler</code></a> which is used when no more specific handlers are registered. On Android, <code>uncaughtExceptionPreHandler</code> is installed as a global coroutine exception handler.</p> <p class="typo-para"><code>CoroutineExceptionHandler</code> is invoked only on <strong class="typo-strong">uncaught</strong> exceptions — exceptions that were not handled in any other way. In particular, all <em>children</em> coroutines (coroutines created in the context of another <a class="typo-link" href="https://kotlin.github.io/kotlinx.coroutines/kotlinx-coroutines-core/kotlinx.coroutines/-job/index.html">Job</a>) delegate handling of their exceptions to their parent coroutine, which also delegates to the parent, and so on until the root, so the <code>CoroutineExceptionHandler</code> installed in their context is never used. In addition to that, <a class="typo-link" href="https://kotlin.github.io/kotlinx.coroutines/kotlinx-coroutines-core/kotlinx.coroutines/async.html">async</a> builder always catches all exceptions and represents them in the resulting <a class="typo-link" href="https://kotlin.github.io/kotlinx.coroutines/kotlinx-coroutines-core/kotlinx.coroutines/-deferred/index.html">Deferred</a> object, so its <code>CoroutineExceptionHandler</code> has no effect either.</p> <blockquote class="typo-quote"> <p class="typo-para">Coroutines running in supervision scope do not propagate exceptions to their parent and are excluded from this rule. A further <a class="typo-link" href="#supervision">Supervision</a> section of this document gives more details.</p> </blockquote> <div class="sample" data-min-compiler-version="1.3"> <pre data-language="kotlin">import kotlinx.coroutines.*

fun main() = runBlocking {
//sampleStart
    val handler = CoroutineExceptionHandler { _, exception -&gt; 
        println("CoroutineExceptionHandler got $exception") 
    }
    val job = GlobalScope.launch(handler) { // root coroutine, running in GlobalScope
        throw AssertionError()
    }
    val deferred = GlobalScope.async(handler) { // also root, but async instead of launch
        throw ArithmeticException() // Nothing will be printed, relying on user to call deferred.await()
    }
    joinAll(job, deferred)
//sampleEnd    
}
</pre> </div> <blockquote class="typo-quote"> <p class="typo-para">You can get the full code <a class="typo-link" href="https://github.com/kotlin/kotlinx.coroutines/blob/master/kotlinx-coroutines-core/jvm/test/guide/example-exceptions-02.kt">here</a>.</p> </blockquote> <p class="typo-para">The output of this code is:</p> <pre>CoroutineExceptionHandler got java.lang.AssertionError
</pre>  <h3 class="typo-header typo-h3" id="cancellation-and-exceptions">Cancellation and exceptions</h3> <p class="typo-para">Cancellation is closely related to exceptions. Coroutines internally use <code>CancellationException</code> for cancellation, these exceptions are ignored by all handlers, so they should be used only as the source of additional debug information, which can be obtained by <code>catch</code> block. When a coroutine is cancelled using <a class="typo-link" href="https://kotlin.github.io/kotlinx.coroutines/kotlinx-coroutines-core/kotlinx.coroutines/-job/cancel.html">Job.cancel</a>, it terminates, but it does not cancel its parent.</p> <div class="sample" data-min-compiler-version="1.3"> <pre data-language="kotlin">import kotlinx.coroutines.*

fun main() = runBlocking {
//sampleStart
    val job = launch {
        val child = launch {
            try {
                delay(Long.MAX_VALUE)
            } finally {
                println("Child is cancelled")
            }
        }
        yield()
        println("Cancelling child")
        child.cancel()
        child.join()
        yield()
        println("Parent is not cancelled")
    }
    job.join()
//sampleEnd    
}
</pre> </div> <blockquote class="typo-quote"> <p class="typo-para">You can get the full code <a class="typo-link" href="https://github.com/kotlin/kotlinx.coroutines/blob/master/kotlinx-coroutines-core/jvm/test/guide/example-exceptions-03.kt">here</a>.</p> </blockquote> <p class="typo-para">The output of this code is:</p> <pre>Cancelling child
Child is cancelled
Parent is not cancelled
</pre>  <p class="typo-para">If a coroutine encounters an exception other than <code>CancellationException</code>, it cancels its parent with that exception. This behaviour cannot be overridden and is used to provide stable coroutines hierarchies for <a class="typo-link" href="https://github.com/Kotlin/kotlinx.coroutines/blob/master/docs/composing-suspending-functions.md#structured-concurrency-with-async">structured concurrency</a>. <a class="typo-link" href="https://kotlin.github.io/kotlinx.coroutines/kotlinx-coroutines-core/kotlinx.coroutines/-coroutine-exception-handler/index.html">CoroutineExceptionHandler</a> implementation is not used for child coroutines.</p> <blockquote class="typo-quote"> <p class="typo-para">In these examples <a class="typo-link" href="https://kotlin.github.io/kotlinx.coroutines/kotlinx-coroutines-core/kotlinx.coroutines/-coroutine-exception-handler/index.html">CoroutineExceptionHandler</a> is always installed to a coroutine that is created in <a class="typo-link" href="https://kotlin.github.io/kotlinx.coroutines/kotlinx-coroutines-core/kotlinx.coroutines/-global-scope/index.html">GlobalScope</a>. It does not make sense to install an exception handler to a coroutine that is launched in the scope of the main <a class="typo-link" href="https://kotlin.github.io/kotlinx.coroutines/kotlinx-coroutines-core/kotlinx.coroutines/run-blocking.html">runBlocking</a>, since the main coroutine is going to be always cancelled when its child completes with exception despite the installed handler.</p> </blockquote> <p class="typo-para">The original exception is handled by the parent only when all its children terminate, which is demonstrated by the following example.</p> <div class="sample" data-min-compiler-version="1.3"> <pre data-language="kotlin">import kotlinx.coroutines.*

fun main() = runBlocking {
//sampleStart
    val handler = CoroutineExceptionHandler { _, exception -&gt; 
        println("CoroutineExceptionHandler got $exception") 
    }
    val job = GlobalScope.launch(handler) {
        launch { // the first child
            try {
                delay(Long.MAX_VALUE)
            } finally {
                withContext(NonCancellable) {
                    println("Children are cancelled, but exception is not handled until all children terminate")
                    delay(100)
                    println("The first child finished its non cancellable block")
                }
            }
        }
        launch { // the second child
            delay(10)
            println("Second child throws an exception")
            throw ArithmeticException()
        }
    }
    job.join()
//sampleEnd    
}
</pre> </div> <blockquote class="typo-quote"> <p class="typo-para">You can get the full code <a class="typo-link" href="https://github.com/kotlin/kotlinx.coroutines/blob/master/kotlinx-coroutines-core/jvm/test/guide/example-exceptions-04.kt">here</a>.</p> </blockquote> <p class="typo-para">The output of this code is:</p> <pre>Second child throws an exception
Children are cancelled, but exception is not handled until all children terminate
The first child finished its non cancellable block
CoroutineExceptionHandler got java.lang.ArithmeticException
</pre>  <h3 class="typo-header typo-h3" id="exceptions-aggregation">Exceptions aggregation</h3> <p class="typo-para">When multiple children of a coroutine fail with an exception, the general rule is "the first exception wins", so the first exception gets handled. All additional exceptions that happen after the first one are attached to the first exception as suppressed ones.</p>  <div class="sample" data-min-compiler-version="1.3"> <pre data-language="kotlin">import kotlinx.coroutines.*
import java.io.*

fun main() = runBlocking {
    val handler = CoroutineExceptionHandler { _, exception -&gt;
        println("CoroutineExceptionHandler got $exception with suppressed ${exception.suppressed.contentToString()}")
    }
    val job = GlobalScope.launch(handler) {
        launch {
            try {
                delay(Long.MAX_VALUE) // it gets cancelled when another sibling fails with IOException
            } finally {
                throw ArithmeticException() // the second exception
            }
        }
        launch {
            delay(100)
            throw IOException() // the first exception
        }
        delay(Long.MAX_VALUE)
    }
    job.join()  
}
</pre> </div> <blockquote class="typo-quote"> <p class="typo-para">You can get the full code <a class="typo-link" href="https://github.com/kotlin/kotlinx.coroutines/blob/master/kotlinx-coroutines-core/jvm/test/guide/example-exceptions-05.kt">here</a>.</p> </blockquote> <blockquote class="typo-quote"> <p class="typo-para">Note: This above code will work properly only on JDK7+ that supports <code>suppressed</code> exceptions</p> </blockquote> <p class="typo-para">The output of this code is:</p> <pre>CoroutineExceptionHandler got java.io.IOException with suppressed [java.lang.ArithmeticException]
</pre>  <blockquote class="typo-quote"> <p class="typo-para">Note that this mechanism currently only works on Java version 1.7+. The JS and Native restrictions are temporary and will be lifted in the future.</p> </blockquote> <p class="typo-para">Cancellation exceptions are transparent and are unwrapped by default:</p> <div class="sample" data-min-compiler-version="1.3"> <pre data-language="kotlin">import kotlinx.coroutines.*
import java.io.*

fun main() = runBlocking {
//sampleStart
    val handler = CoroutineExceptionHandler { _, exception -&gt;
        println("CoroutineExceptionHandler got $exception")
    }
    val job = GlobalScope.launch(handler) {
        val inner = launch { // all this stack of coroutines will get cancelled
            launch {
                launch {
                    throw IOException() // the original exception
                }
            }
        }
        try {
            inner.join()
        } catch (e: CancellationException) {
            println("Rethrowing CancellationException with original cause")
            throw e // cancellation exception is rethrown, yet the original IOException gets to the handler  
        }
    }
    job.join()
//sampleEnd    
}
</pre> </div> <blockquote class="typo-quote"> <p class="typo-para">You can get the full code <a class="typo-link" href="https://github.com/kotlin/kotlinx.coroutines/blob/master/kotlinx-coroutines-core/jvm/test/guide/example-exceptions-06.kt">here</a>.</p> </blockquote> <p class="typo-para">The output of this code is:</p> <pre>Rethrowing CancellationException with original cause
CoroutineExceptionHandler got java.io.IOException
</pre>  <h3 class="typo-header typo-h3" id="supervision">Supervision</h3> <p class="typo-para">As we have studied before, cancellation is a bidirectional relationship propagating through the whole hierarchy of coroutines. Let us take a look at the case when unidirectional cancellation is required.</p> <p class="typo-para">A good example of such a requirement is a UI component with the job defined in its scope. If any of the UI's child tasks have failed, it is not always necessary to cancel (effectively kill) the whole UI component, but if UI component is destroyed (and its job is cancelled), then it is necessary to fail all child jobs as their results are no longer needed.</p> <p class="typo-para">Another example is a server process that spawns multiple child jobs and needs to <em>supervise</em> their execution, tracking their failures and only restarting the failed ones.</p> <h4 class="typo-header typo-h4" id="supervision-job">Supervision job</h4> <p class="typo-para">The <a class="typo-link" href="https://kotlin.github.io/kotlinx.coroutines/kotlinx-coroutines-core/kotlinx.coroutines/-supervisor-job.html">SupervisorJob</a> can be used for these purposes. It is similar to a regular <a class="typo-link" href="https://kotlin.github.io/kotlinx.coroutines/kotlinx-coroutines-core/kotlinx.coroutines/-job.html">Job</a> with the only exception that cancellation is propagated only downwards. This can easily be demonstrated using the following example:</p> <div class="sample"> <pre data-language="kotlin">import kotlinx.coroutines.*

fun main() = runBlocking {
    val supervisor = SupervisorJob()
    with(CoroutineScope(coroutineContext + supervisor)) {
        // launch the first child -- its exception is ignored for this example (don't do this in practice!)
        val firstChild = launch(CoroutineExceptionHandler { _, _ -&gt;  }) {
            println("The first child is failing")
            throw AssertionError("The first child is cancelled")
        }
        // launch the second child
        val secondChild = launch {
            firstChild.join()
            // Cancellation of the first child is not propagated to the second child
            println("The first child is cancelled: ${firstChild.isCancelled}, but the second one is still active")
            try {
                delay(Long.MAX_VALUE)
            } finally {
                // But cancellation of the supervisor is propagated
                println("The second child is cancelled because the supervisor was cancelled")
            }
        }
        // wait until the first child fails &amp; completes
        firstChild.join()
        println("Cancelling the supervisor")
        supervisor.cancel()
        secondChild.join()
    }
}
</pre> </div> <blockquote class="typo-quote"> <p class="typo-para">You can get the full code <a class="typo-link" href="https://github.com/kotlin/kotlinx.coroutines/blob/master/kotlinx-coroutines-core/jvm/test/guide/example-supervision-01.kt">here</a>.</p> </blockquote> <p class="typo-para">The output of this code is:</p> <pre>The first child is failing
The first child is cancelled: true, but the second one is still active
Cancelling the supervisor
The second child is cancelled because the supervisor was cancelled
</pre>  <h4 class="typo-header typo-h4" id="supervision-scope">Supervision scope</h4> <p class="typo-para">Instead of <a class="typo-link" href="https://kotlin.github.io/kotlinx.coroutines/kotlinx-coroutines-core/kotlinx.coroutines/coroutine-scope.html">coroutineScope</a>, we can use <a class="typo-link" href="https://kotlin.github.io/kotlinx.coroutines/kotlinx-coroutines-core/kotlinx.coroutines/supervisor-scope.html">supervisorScope</a> for <em>scoped</em> concurrency. It propagates the cancellation in one direction only and cancels all its children only if it failed itself. It also waits for all children before completion just like <a class="typo-link" href="https://kotlin.github.io/kotlinx.coroutines/kotlinx-coroutines-core/kotlinx.coroutines/coroutine-scope.html">coroutineScope</a> does.</p> <div class="sample"> <pre data-language="kotlin">import kotlin.coroutines.*
import kotlinx.coroutines.*

fun main() = runBlocking {
    try {
        supervisorScope {
            val child = launch {
                try {
                    println("The child is sleeping")
                    delay(Long.MAX_VALUE)
                } finally {
                    println("The child is cancelled")
                }
            }
            // Give our child a chance to execute and print using yield 
            yield()
            println("Throwing an exception from the scope")
            throw AssertionError()
        }
    } catch(e: AssertionError) {
        println("Caught an assertion error")
    }
}
</pre> </div> <blockquote class="typo-quote"> <p class="typo-para">You can get the full code <a class="typo-link" href="https://github.com/kotlin/kotlinx.coroutines/blob/master/kotlinx-coroutines-core/jvm/test/guide/example-supervision-02.kt">here</a>.</p> </blockquote> <p class="typo-para">The output of this code is:</p> <pre>The child is sleeping
Throwing an exception from the scope
The child is cancelled
Caught an assertion error
</pre>  <h4 class="typo-header typo-h4" id="exceptions-in-supervised-coroutines">Exceptions in supervised coroutines</h4> <p class="typo-para">Another crucial difference between regular and supervisor jobs is exception handling. Every child should handle its exceptions by itself via the exception handling mechanism. This difference comes from the fact that child's failure does not propagate to the parent. It means that coroutines launched directly inside the <a class="typo-link" href="https://kotlin.github.io/kotlinx.coroutines/kotlinx-coroutines-core/kotlinx.coroutines/supervisor-scope.html">supervisorScope</a> <em>do</em> use the <a class="typo-link" href="https://kotlin.github.io/kotlinx.coroutines/kotlinx-coroutines-core/kotlinx.coroutines/-coroutine-exception-handler/index.html">CoroutineExceptionHandler</a> that is installed in their scope in the same way as root coroutines do (see the <a class="typo-link" href="#coroutineexceptionhandler">CoroutineExceptionHandler</a> section for details).</p> <div class="sample"> <pre data-language="kotlin">import kotlin.coroutines.*
import kotlinx.coroutines.*

fun main() = runBlocking {
    val handler = CoroutineExceptionHandler { _, exception -&gt; 
        println("CoroutineExceptionHandler got $exception") 
    }
    supervisorScope {
        val child = launch(handler) {
            println("The child throws an exception")
            throw AssertionError()
        }
        println("The scope is completing")
    }
    println("The scope is completed")
}
</pre> </div> <blockquote class="typo-quote"> <p class="typo-para">You can get the full code <a class="typo-link" href="https://github.com/kotlin/kotlinx.coroutines/blob/master/kotlinx-coroutines-core/jvm/test/guide/example-supervision-03.kt">here</a>.</p> </blockquote> <p class="typo-para">The output of this code is:</p> <pre>The scope is completing
The child throws an exception
CoroutineExceptionHandler got java.lang.AssertionError
The scope is completed
</pre>
<div class="_attribution">
  <p class="_attribution-p">
    © 2010–2020 JetBrains s.r.o. and Kotlin Programming Language contributors<br>Licensed under the Apache License, Version 2.0.<br>
    <a href="https://kotlinlang.org/docs/reference/coroutines/exception-handling.html" class="_attribution-link">https://kotlinlang.org/docs/reference/coroutines/exception-handling.html</a>
  </p>
</div>

				
			</div>
			<ins class="adsbygoogle"
     style="display:block"
     data-ad-client="ca-pub-2572770204602497"
     data-ad-slot="1992473792"
     data-ad-format="auto"
     data-full-width-responsive="true"></ins>
<script>
     (adsbygoogle = window.adsbygoogle || []).push({});
</script>
		</div>
	</section>

	</div>
	<svg style="display:none">
		<symbol id="icon-dir"><svg viewBox="0 0 20 20"><path d="M15 10c0 .3-.305.515-.305.515l-8.56 5.303c-.625.41-1.135.106-1.135-.67V4.853c0-.777.51-1.078 1.135-.67l8.56 5.305S15 9.702 15 10z"/></svg></symbol>
	  </svg>
</body>
</html>
