
<!DOCTYPE HTML>

<html lang="en" class="_theme-default">

<head>
  <meta charset="utf-8">
  <title>Django Exceptions - Django 3.1 - W3cubDocs</title>
  
  <meta name="description" content=" Django raises some of its own exceptions as well as standard Python exceptions. ">
  <meta name="keywords" content="django, exceptions, django~3.1">
  <meta name="HandheldFriendly" content="True">
  <meta name="MobileOptimized" content="320">
  <meta name="viewport" content="width=device-width, initial-scale=1">
  <meta name="mobile-web-app-capable" content="yes">
  
  <link rel="canonical" href="https://docs.w3cub.com/django~3.1/ref/exceptions.html">
  <link href="/favicon.png" rel="icon">
  <link rel="stylesheet" type="text/css" href="/assets/application-01fda2ddb8339756caccf7add5ad4cf849ab52d069bd799015c7f04f93164f64753bff0d15a49d8060b1e66e41002bb301ccadc2350937df079cea3cd52d3cca.css">
  <script src="/assets/application-d9be6f56a823612443fc15b2e027a630e02c4ad2685bb750d13fa4fae28d46c3e7f7ebb69bd4bafddf116f218f9372e9be44021d4247dc20424e2fd1ff8cef81.js" type="text/javascript"></script>
  <script src="/json/django~3.1.js"></script>
  
  <script type="text/javascript">
    var _gaq = _gaq || [];
    _gaq.push(['_setAccount', 'UA-71174418-1']);
    _gaq.push(['_trackPageview']);

    (function() {
      var ga = document.createElement('script'); ga.type = 'text/javascript'; ga.async = true;
      ga.src = ('https:' == document.location.protocol ? 'https://ssl' : 'http://www') + '.google-analytics.com/ga.js';
      var s = document.getElementsByTagName('script')[0]; s.parentNode.insertBefore(ga, s);
    })();
  </script>
  <script data-ad-client="ca-pub-2572770204602497" async src="https://pagead2.googlesyndication.com/pagead/js/adsbygoogle.js"></script>
  <script async custom-element="amp-auto-ads"
  src="https://cdn.ampproject.org/v0/amp-auto-ads-0.1.js">
</script>


</head>

<body class="docs">
	<amp-auto-ads type="adsense"
              data-ad-client="ca-pub-2572770204602497">
	</amp-auto-ads>
	<div class="_app">
	<header class="_header">

  <a class="_home-link" href="/" ></a>
  <a class="_menu-link"></a>
  <h1 class="_logo">
    <a href="/" class="_nav-link" title="API Documentation Browser">W3cubDocs</a>
  </h1>
  
  <span class="_logo-sub-nav">/</span><span class="_logo-sub-nav"><a href="/django~3.1/" class="_nav-link" title="" style="margin-left:0;">Django 3.1</a></span>
  
  <nav class="_nav">
    <a href="https://tools.w3cub.com/?_sp=docs" target="_blank" class="_nav-link ">W3cubTools</a>
    <a href="/cheatsheets/" class="_nav-link ">Cheatsheets</a>
    <a href="/about/" class="_nav-link ">About</a>
  </nav>
</header>
	<section class="_sidebar">
		
		<form class="_search">
		  <input type="search" class="_search-input" placeholder="Search&hellip;" autocomplete="off" autocapitalize="off" autocorrect="off" spellcheck="false" maxlength="20">
		  <a class="_search-clear"></a>
		  <div class="_search-tag"></div>
		</form>
		
		<div class="_list-wrap">
			<div class="_list">
			
			</div>
		</div>
	</section>
	<section class="_container ">
		<div class="_content">
			<ins class="adsbygoogle"
     style="display:block"
     data-ad-client="ca-pub-2572770204602497"
     data-ad-slot="6861657091"
     data-ad-format="link"
     data-full-width-responsive="true"></ins>
<script>
     (adsbygoogle = window.adsbygoogle || []).push({});
</script>
			<div class="_page _sphinx">
				
				
<h1 id="django-exceptions">Django Exceptions</h1> <p id="s-django-exceptions">Django raises some of its own exceptions as well as standard Python exceptions.</p>  <h2 id="django-core-exceptions">Django Core Exceptions</h2> <p id="s-module-django.core.exceptions">Django core exception classes are defined in <code>django.core.exceptions</code>.</p>  <h3 id="appregistrynotready"><code>AppRegistryNotReady</code></h3> <dl class="exception" id="s-appregistrynotready"> <dt id="django.core.exceptions.AppRegistryNotReady">
<code>exception AppRegistryNotReady</code> <a class="reference internal" href="https://docs.djangoproject.com/en/3.1/_modules/django/core/exceptions/#AppRegistryNotReady"><span class="viewcode-link">[source]</span></a>
</dt> <dd>
<p>This exception is raised when attempting to use models before the <a class="reference internal" href="applications#app-loading-process"><span class="std std-ref">app loading process</span></a>, which initializes the ORM, is complete.</p> </dd>
</dl>   <h3 id="objectdoesnotexist"><code>ObjectDoesNotExist</code></h3> <dl class="exception" id="s-objectdoesnotexist"> <dt id="django.core.exceptions.ObjectDoesNotExist">
<code>exception ObjectDoesNotExist</code> <a class="reference internal" href="https://docs.djangoproject.com/en/3.1/_modules/django/core/exceptions/#ObjectDoesNotExist"><span class="viewcode-link">[source]</span></a>
</dt> <dd>
<p>The base class for <a class="reference internal" href="models/class#django.db.models.Model.DoesNotExist" title="django.db.models.Model.DoesNotExist"><code>Model.DoesNotExist</code></a> exceptions. A <code>try/except</code> for <code>ObjectDoesNotExist</code> will catch <a class="reference internal" href="models/class#django.db.models.Model.DoesNotExist" title="django.db.models.Model.DoesNotExist"><code>DoesNotExist</code></a> exceptions for all models.</p> <p>See <a class="reference internal" href="models/querysets#django.db.models.query.QuerySet.get" title="django.db.models.query.QuerySet.get"><code>get()</code></a>.</p> </dd>
</dl>   <h3 id="emptyresultset"><code>EmptyResultSet</code></h3> <dl class="exception" id="s-emptyresultset"> <dt id="django.core.exceptions.EmptyResultSet">
<code>exception EmptyResultSet</code> <a class="reference internal" href="https://docs.djangoproject.com/en/3.1/_modules/django/core/exceptions/#EmptyResultSet"><span class="viewcode-link">[source]</span></a>
</dt> <dd>
<p><code>EmptyResultSet</code> may be raised during query generation if a query won’t return any results. Most Django projects won’t encounter this exception, but it might be useful for implementing custom lookups and expressions.</p> </dd>
</dl>   <h3 id="fielddoesnotexist"><code>FieldDoesNotExist</code></h3> <dl class="exception" id="s-fielddoesnotexist"> <dt id="django.core.exceptions.FieldDoesNotExist">
<code>exception FieldDoesNotExist</code> <a class="reference internal" href="https://docs.djangoproject.com/en/3.1/_modules/django/core/exceptions/#FieldDoesNotExist"><span class="viewcode-link">[source]</span></a>
</dt> <dd>
<p>The <code>FieldDoesNotExist</code> exception is raised by a model’s <code>_meta.get_field()</code> method when the requested field does not exist on the model or on the model’s parents.</p> </dd>
</dl>   <h3 id="multipleobjectsreturned"><code>MultipleObjectsReturned</code></h3> <dl class="exception" id="s-multipleobjectsreturned"> <dt id="django.core.exceptions.MultipleObjectsReturned">
<code>exception MultipleObjectsReturned</code> <a class="reference internal" href="https://docs.djangoproject.com/en/3.1/_modules/django/core/exceptions/#MultipleObjectsReturned"><span class="viewcode-link">[source]</span></a>
</dt> <dd>
<p>The base class for <a class="reference internal" href="models/class#django.db.models.Model.MultipleObjectsReturned" title="django.db.models.Model.MultipleObjectsReturned"><code>Model.MultipleObjectsReturned</code></a> exceptions. A <code>try/except</code> for <code>MultipleObjectsReturned</code> will catch <a class="reference internal" href="models/class#django.db.models.Model.MultipleObjectsReturned" title="django.db.models.Model.MultipleObjectsReturned"><code>MultipleObjectsReturned</code></a> exceptions for all models.</p> <p>See <a class="reference internal" href="models/querysets#django.db.models.query.QuerySet.get" title="django.db.models.query.QuerySet.get"><code>get()</code></a>.</p> </dd>
</dl>   <h3 id="suspiciousoperation"><code>SuspiciousOperation</code></h3> <dl class="exception" id="s-suspiciousoperation"> <dt id="django.core.exceptions.SuspiciousOperation">
<code>exception SuspiciousOperation</code> <a class="reference internal" href="https://docs.djangoproject.com/en/3.1/_modules/django/core/exceptions/#SuspiciousOperation"><span class="viewcode-link">[source]</span></a>
</dt> <dd>
<p>The <a class="reference internal" href="#django.core.exceptions.SuspiciousOperation" title="django.core.exceptions.SuspiciousOperation"><code>SuspiciousOperation</code></a> exception is raised when a user has performed an operation that should be considered suspicious from a security perspective, such as tampering with a session cookie. Subclasses of <code>SuspiciousOperation</code> include:</p> <ul class="simple"> <li><code>DisallowedHost</code></li> <li><code>DisallowedModelAdminLookup</code></li> <li><code>DisallowedModelAdminToField</code></li> <li><code>DisallowedRedirect</code></li> <li><code>InvalidSessionKey</code></li> <li><code>RequestDataTooBig</code></li> <li><code>SuspiciousFileOperation</code></li> <li><code>SuspiciousMultipartForm</code></li> <li><code>SuspiciousSession</code></li> <li><code>TooManyFieldsSent</code></li> </ul> <p>If a <code>SuspiciousOperation</code> exception reaches the ASGI/WSGI handler level it is logged at the <code>Error</code> level and results in a <a class="reference internal" href="request-response#django.http.HttpResponseBadRequest" title="django.http.HttpResponseBadRequest"><code>HttpResponseBadRequest</code></a>. See the <a class="reference internal" href="../topics/logging"><span class="doc">logging documentation</span></a> for more information.</p> </dd>
</dl>   <h3 id="permissiondenied"><code>PermissionDenied</code></h3> <dl class="exception" id="s-permissiondenied"> <dt id="django.core.exceptions.PermissionDenied">
<code>exception PermissionDenied</code> <a class="reference internal" href="https://docs.djangoproject.com/en/3.1/_modules/django/core/exceptions/#PermissionDenied"><span class="viewcode-link">[source]</span></a>
</dt> <dd>
<p>The <a class="reference internal" href="#django.core.exceptions.PermissionDenied" title="django.core.exceptions.PermissionDenied"><code>PermissionDenied</code></a> exception is raised when a user does not have permission to perform the action requested.</p> </dd>
</dl>   <h3 id="viewdoesnotexist"><code>ViewDoesNotExist</code></h3> <dl class="exception" id="s-viewdoesnotexist"> <dt id="django.core.exceptions.ViewDoesNotExist">
<code>exception ViewDoesNotExist</code> <a class="reference internal" href="https://docs.djangoproject.com/en/3.1/_modules/django/core/exceptions/#ViewDoesNotExist"><span class="viewcode-link">[source]</span></a>
</dt> <dd>
<p>The <a class="reference internal" href="#django.core.exceptions.ViewDoesNotExist" title="django.core.exceptions.ViewDoesNotExist"><code>ViewDoesNotExist</code></a> exception is raised by <a class="reference internal" href="urlresolvers#module-django.urls" title="django.urls"><code>django.urls</code></a> when a requested view does not exist.</p> </dd>
</dl>   <h3 id="middlewarenotused"><code>MiddlewareNotUsed</code></h3> <dl class="exception" id="s-middlewarenotused"> <dt id="django.core.exceptions.MiddlewareNotUsed">
<code>exception MiddlewareNotUsed</code> <a class="reference internal" href="https://docs.djangoproject.com/en/3.1/_modules/django/core/exceptions/#MiddlewareNotUsed"><span class="viewcode-link">[source]</span></a>
</dt> <dd>
<p>The <a class="reference internal" href="#django.core.exceptions.MiddlewareNotUsed" title="django.core.exceptions.MiddlewareNotUsed"><code>MiddlewareNotUsed</code></a> exception is raised when a middleware is not used in the server configuration.</p> </dd>
</dl>   <h3 id="improperlyconfigured"><code>ImproperlyConfigured</code></h3> <dl class="exception" id="s-improperlyconfigured"> <dt id="django.core.exceptions.ImproperlyConfigured">
<code>exception ImproperlyConfigured</code> <a class="reference internal" href="https://docs.djangoproject.com/en/3.1/_modules/django/core/exceptions/#ImproperlyConfigured"><span class="viewcode-link">[source]</span></a>
</dt> <dd>
<p>The <a class="reference internal" href="#django.core.exceptions.ImproperlyConfigured" title="django.core.exceptions.ImproperlyConfigured"><code>ImproperlyConfigured</code></a> exception is raised when Django is somehow improperly configured – for example, if a value in <code>settings.py</code> is incorrect or unparseable.</p> </dd>
</dl>   <h3 id="fielderror"><code>FieldError</code></h3> <dl class="exception" id="s-fielderror"> <dt id="django.core.exceptions.FieldError">
<code>exception FieldError</code> <a class="reference internal" href="https://docs.djangoproject.com/en/3.1/_modules/django/core/exceptions/#FieldError"><span class="viewcode-link">[source]</span></a>
</dt> <dd>
<p>The <a class="reference internal" href="#django.core.exceptions.FieldError" title="django.core.exceptions.FieldError"><code>FieldError</code></a> exception is raised when there is a problem with a model field. This can happen for several reasons:</p> <ul class="simple"> <li>A field in a model clashes with a field of the same name from an abstract base class</li> <li>An infinite loop is caused by ordering</li> <li>A keyword cannot be parsed from the filter parameters</li> <li>A field cannot be determined from a keyword in the query parameters</li> <li>A join is not permitted on the specified field</li> <li>A field name is invalid</li> <li>A query contains invalid order_by arguments</li> </ul> </dd>
</dl>   <h3 id="validationerror"><code>ValidationError</code></h3> <dl class="exception" id="s-validationerror"> <dt id="django.core.exceptions.ValidationError">
<code>exception ValidationError</code> <a class="reference internal" href="https://docs.djangoproject.com/en/3.1/_modules/django/core/exceptions/#ValidationError"><span class="viewcode-link">[source]</span></a>
</dt> <dd>
<p>The <a class="reference internal" href="#django.core.exceptions.ValidationError" title="django.core.exceptions.ValidationError"><code>ValidationError</code></a> exception is raised when data fails form or model field validation. For more information about validation, see <a class="reference internal" href="forms/validation"><span class="doc">Form and Field Validation</span></a>, <a class="reference internal" href="models/instances#validating-objects"><span class="std std-ref">Model Field Validation</span></a> and the <a class="reference internal" href="validators"><span class="doc">Validator Reference</span></a>.</p> </dd>
</dl>  <h4 id="non-field-errors"><code>NON_FIELD_ERRORS</code></h4> <dl class="data" id="s-non-field-errors"> <dt id="django.core.exceptions.NON_FIELD_ERRORS">
<code>NON_FIELD_ERRORS</code> </dt> 
</dl> <p><code>ValidationError</code>s that don’t belong to a particular field in a form or model are classified as <code>NON_FIELD_ERRORS</code>. This constant is used as a key in dictionaries that otherwise map fields to their respective list of errors.</p>    <h3 id="requestaborted"><code>RequestAborted</code></h3> <dl class="exception" id="s-requestaborted"> <dt id="django.core.exceptions.RequestAborted">
<code>exception RequestAborted</code> <a class="reference internal" href="https://docs.djangoproject.com/en/3.1/_modules/django/core/exceptions/#RequestAborted"><span class="viewcode-link">[source]</span></a>
</dt> <dd>
<div class="versionadded"> <span class="title">New in Django 3.0.</span> </div> <p>The <a class="reference internal" href="#django.core.exceptions.RequestAborted" title="django.core.exceptions.RequestAborted"><code>RequestAborted</code></a> exception is raised when a HTTP body being read in by the handler is cut off midstream and the client connection closes, or when the client does not send data and hits a timeout where the server closes the connection.</p> <p>It is internal to the HTTP handler modules and you are unlikely to see it elsewhere. If you are modifying HTTP handling code, you should raise this when you encounter an aborted request to make sure the socket is closed cleanly.</p> </dd>
</dl>   <h3 id="synchronousonlyoperation"><code>SynchronousOnlyOperation</code></h3> <dl class="exception" id="s-synchronousonlyoperation"> <dt id="django.core.exceptions.SynchronousOnlyOperation">
<code>exception SynchronousOnlyOperation</code> <a class="reference internal" href="https://docs.djangoproject.com/en/3.1/_modules/django/core/exceptions/#SynchronousOnlyOperation"><span class="viewcode-link">[source]</span></a>
</dt> <dd>
<div class="versionadded"> <span class="title">New in Django 3.0.</span> </div> <p>The <a class="reference internal" href="#django.core.exceptions.SynchronousOnlyOperation" title="django.core.exceptions.SynchronousOnlyOperation"><code>SynchronousOnlyOperation</code></a> exception is raised when code that is only allowed in synchronous Python code is called from an asynchronous context (a thread with a running asynchronous event loop). These parts of Django are generally heavily reliant on thread-safety to function and don’t work correctly under coroutines sharing the same thread.</p> <p>If you are trying to call code that is synchronous-only from an asynchronous thread, then create a synchronous thread and call it in that. You can accomplish this is with <a class="reference internal" href="../topics/async#asgiref.sync.sync_to_async" title="asgiref.sync.sync_to_async"><code>asgiref.sync.sync_to_async()</code></a>.</p> </dd>
</dl>    <h2 id="url-resolver-exceptions">URL Resolver exceptions</h2> <p id="s-url-resolver-exceptions">URL Resolver exceptions are defined in <code>django.urls</code>.</p>  <h3 id="resolver404"><code>Resolver404</code></h3> <dl class="exception" id="s-resolver404"> <dt id="django.urls.Resolver404">
<code>exception Resolver404</code> </dt> <dd>
<p>The <a class="reference internal" href="#django.urls.Resolver404" title="django.urls.Resolver404"><code>Resolver404</code></a> exception is raised by <a class="reference internal" href="urlresolvers#django.urls.resolve" title="django.urls.resolve"><code>resolve()</code></a> if the path passed to <code>resolve()</code> doesn’t map to a view. It’s a subclass of <a class="reference internal" href="../topics/http/views#django.http.Http404" title="django.http.Http404"><code>django.http.Http404</code></a>.</p> </dd>
</dl>   <h3 id="noreversematch"><code>NoReverseMatch</code></h3> <dl class="exception" id="s-noreversematch"> <dt id="django.urls.NoReverseMatch">
<code>exception NoReverseMatch</code> </dt> <dd>
<p>The <a class="reference internal" href="#django.urls.NoReverseMatch" title="django.urls.NoReverseMatch"><code>NoReverseMatch</code></a> exception is raised by <a class="reference internal" href="urlresolvers#module-django.urls" title="django.urls"><code>django.urls</code></a> when a matching URL in your URLconf cannot be identified based on the parameters supplied.</p> </dd>
</dl>    <h2 id="database-exceptions">Database Exceptions</h2> <p id="s-database-exceptions">Database exceptions may be imported from <code>django.db</code>.</p> <p>Django wraps the standard database exceptions so that your Django code has a guaranteed common implementation of these classes.</p> <dl class="exception"> <dt id="django.db.Error">
<code>exception Error</code> </dt> 
</dl> <dl class="exception"> <dt id="django.db.InterfaceError">
<code>exception InterfaceError</code> </dt> 
</dl> <dl class="exception"> <dt id="django.db.DatabaseError">
<code>exception DatabaseError</code> </dt> 
</dl> <dl class="exception"> <dt id="django.db.DataError">
<code>exception DataError</code> </dt> 
</dl> <dl class="exception"> <dt id="django.db.OperationalError">
<code>exception OperationalError</code> </dt> 
</dl> <dl class="exception"> <dt id="django.db.IntegrityError">
<code>exception IntegrityError</code> </dt> 
</dl> <dl class="exception"> <dt id="django.db.InternalError">
<code>exception InternalError</code> </dt> 
</dl> <dl class="exception"> <dt id="django.db.ProgrammingError">
<code>exception ProgrammingError</code> </dt> 
</dl> <dl class="exception"> <dt id="django.db.NotSupportedError">
<code>exception NotSupportedError</code> </dt> 
</dl> <p>The Django wrappers for database exceptions behave exactly the same as the underlying database exceptions. See <a class="pep reference external" href="https://www.python.org/dev/peps/pep-0249" id="index-0"><strong>PEP 249</strong></a>, the Python Database API Specification v2.0, for further information.</p> <p>As per <a class="pep reference external" href="https://www.python.org/dev/peps/pep-3134" id="index-1"><strong>PEP 3134</strong></a>, a <code>__cause__</code> attribute is set with the original (underlying) database exception, allowing access to any additional information provided.</p> <dl class="exception"> <dt id="django.db.models.ProtectedError">
<code>exception models.ProtectedError</code> </dt> 
</dl> <p>Raised to prevent deletion of referenced objects when using <a class="reference internal" href="models/fields#django.db.models.PROTECT" title="django.db.models.PROTECT"><code>django.db.models.PROTECT</code></a>. <a class="reference internal" href="#django.db.models.ProtectedError" title="django.db.models.ProtectedError"><code>models.ProtectedError</code></a> is a subclass of <a class="reference internal" href="#django.db.IntegrityError" title="django.db.IntegrityError"><code>IntegrityError</code></a>.</p> <dl class="exception"> <dt id="django.db.models.RestrictedError">
<code>exception models.RestrictedError</code> </dt> 
</dl> <p>Raised to prevent deletion of referenced objects when using <a class="reference internal" href="models/fields#django.db.models.RESTRICT" title="django.db.models.RESTRICT"><code>django.db.models.RESTRICT</code></a>. <a class="reference internal" href="#django.db.models.RestrictedError" title="django.db.models.RestrictedError"><code>models.RestrictedError</code></a> is a subclass of <a class="reference internal" href="#django.db.IntegrityError" title="django.db.IntegrityError"><code>IntegrityError</code></a>.</p>   <h2 id="http-exceptions">Http Exceptions</h2> <p id="s-http-exceptions">Http exceptions may be imported from <code>django.http</code>.</p>  <h3 id="unreadableposterror"><code>UnreadablePostError</code></h3> <dl class="exception" id="s-unreadableposterror"> <dt id="django.http.UnreadablePostError">
<code>exception UnreadablePostError</code> </dt> <dd>
<p><a class="reference internal" href="#django.http.UnreadablePostError" title="django.http.UnreadablePostError"><code>UnreadablePostError</code></a> is raised when a user cancels an upload.</p> </dd>
</dl>    <h2 id="transaction-exceptions">Transaction Exceptions</h2> <p id="s-transaction-exceptions">Transaction exceptions are defined in <code>django.db.transaction</code>.</p>  <h3 id="transactionmanagementerror"><code>TransactionManagementError</code></h3> <dl class="exception" id="s-transactionmanagementerror"> <dt id="django.db.transaction.TransactionManagementError">
<code>exception TransactionManagementError</code> </dt> <dd>
<p><a class="reference internal" href="#django.db.transaction.TransactionManagementError" title="django.db.transaction.TransactionManagementError"><code>TransactionManagementError</code></a> is raised for any and all problems related to database transactions.</p> </dd>
</dl>    <h2 id="testing-framework-exceptions">Testing Framework Exceptions</h2> <p id="s-testing-framework-exceptions">Exceptions provided by the <code>django.test</code> package.</p>  <h3 id="redirectcycleerror"><code>RedirectCycleError</code></h3> <dl class="exception" id="s-redirectcycleerror"> <dt id="django.test.client.RedirectCycleError">
<code>exception client.RedirectCycleError</code> </dt> <dd>
<p><a class="reference internal" href="#django.test.client.RedirectCycleError" title="django.test.client.RedirectCycleError"><code>RedirectCycleError</code></a> is raised when the test client detects a loop or an overly long chain of redirects.</p> </dd>
</dl>    <h2 id="python-exceptions">Python Exceptions</h2> <p id="s-python-exceptions">Django raises built-in Python exceptions when appropriate as well. See the Python documentation for further information on the <a class="reference external" href="https://docs.python.org/3/library/exceptions.html#bltin-exceptions" title="(in Python v3.9)"><span>Built-in Exceptions</span></a>.</p>
<div class="_attribution">
  <p class="_attribution-p">
    © Django Software Foundation and individual contributors<br>Licensed under the BSD License.<br>
    <a href="https://docs.djangoproject.com/en/3.1/ref/exceptions/" class="_attribution-link">https://docs.djangoproject.com/en/3.1/ref/exceptions/</a>
  </p>
</div>

				
			</div>
			<ins class="adsbygoogle"
     style="display:block"
     data-ad-client="ca-pub-2572770204602497"
     data-ad-slot="1992473792"
     data-ad-format="auto"
     data-full-width-responsive="true"></ins>
<script>
     (adsbygoogle = window.adsbygoogle || []).push({});
</script>
		</div>
	</section>

	</div>
	<svg style="display:none">
		<symbol id="icon-dir"><svg viewBox="0 0 20 20"><path d="M15 10c0 .3-.305.515-.305.515l-8.56 5.303c-.625.41-1.135.106-1.135-.67V4.853c0-.777.51-1.078 1.135-.67l8.56 5.305S15 9.702 15 10z"/></svg></symbol>
	  </svg>
</body>
</html>
